Workbook

Sheet JANEIRO 2025
N1: =SUBTOTAL(9,Tabela13891011121314[Match_Planilha]) -> 230480.79 | O1: =SUBTOTAL(9,Tabela13891011121314[Dif]) -> 0
A2: DT | B2: Data coleta | C2: Coluna1 | D2: Cliente/Fornecedor | E2: Local | F2: Numero NF | G2: Data canhoto | H2: Data recibo | I2: Valor recibo | J2: Scaner | K2: Drive-ANEXO | L2: status forms | M2: DATA LANÇAMENTO | N2: Match_Planilha | O2: Dif | P2: obs
A3: 19206445 | F3: 47486/47488/47487/47489/47485 | G3: 45653 | H3: 45653 | I3: 208 | J3: OK | L3: LANÇADO | M3: 45659 | N3: =Tabela13891011121314[[#This Row],[Valor recibo]] -> 208
A4: 19223330 | F4: 47834 | G4: 45656 | H4: 45656 | I4: 210 | J4: OK | L4: LANÇADO | M4: 45659 | N4: =Tabela13891011121314[[#This Row],[Valor recibo]] -> 210
A5: 19210921 | F5: 47647/47646 | G5: 45654 | H5: 45654 | I5: 338.8 | J5: OK | L5: LANÇADO | M5: 45659 | N5: =Tabela13891011121314[[#This Row],[Valor recibo]] -> 338.8
A6: 19228621 | F6: 48072/48070 | G6: 45657 | H6: 45657 | I6: 448 | J6: OK | L6: LANÇADO | M6: 45659 | N6: =Tabela13891011121314[[#This Row],[Valor recibo]] -> 448
A7: 19223335 | F7: 48040/48039/48037/48038 | G7: 45657 | H7: 45657 | I7: 420 | J7: OK | L7: LANÇADO | M7: 45659 | N7: =Tabela13891011121314[[#This Row],[Valor recibo]] -> 420
A8: 19229137 | F8: 47948/47947/47949 | G8: 45656 | H8: 45687 | I8: 224 | J8: OK | L8: LANÇADO | M8: 45659 | N8: =Tabela13891011121314[[#This Row],[Valor recibo]] -> 224
A9: 19223338 | F9: 48242 | G9: 45659 | H9: 45659 | I9: 420 | J9: OK | L9: LANÇADO | M9: 45659 | N9: =Tabela13891011121314[[#This Row],[Valor recibo]] -> 420
A10: 19223266 | F10: 48371 | G10: 45659 | H10: 45659 | I10: 210 | J10: OK | L10: LANÇADO | M10: 45659 | N10: =Tabela13891011121314[[#This Row],[Valor recibo]] -> 210
A11: 19222452 | F11: 48330/48329 | G11: 45659 | H11: 45659 | I11: 0 | J11: OK | N11: =Tabela13891011121314[[#This Row],[Valor recibo]] -> 0
A12: 19230296 | F12: 48312/48311/48310 | G12: 45659 | H12: 45659 | I12: 0 | J12: OK | N12: =Tabela13891011121314[[#This Row],[Valor recibo]] -> 0
A13: 19230316 | F13: 48267/48269/48268 | G13: 45659 | H13: 45659 | I13: 238 | J13: OK | L13: LANÇADO | M13: 45659 | N13: =Tabela13891011121314[[#This Row],[Valor recibo]] -> 238
A14: 19230340 | F14: 48298/48295/48296/48297 | G14: 45659 | H14: 45659 | I14: 238 | J14: OK | L14: LANÇADO | M14: 45659 | N14: =Tabela13891011121314[[#This Row],[Valor recibo]] -> 238
A15: 19223294 | F15: 48316/48315 | G15: 45659 | H15: 45659 | I15: 210 | J15: OK | L15: LANÇADO | M15: 45659 | N15: =Tabela13891011121314[[#This Row],[Valor recibo]] -> 210
A16: 19224723 | F16: 48293 | G16: 45659 | H16: 45659 | I16: 184.21 | J16: OK | L16: LANÇADO | M16: 45659 | N16: =Tabela13891011121314[[#This Row],[Valor recibo]] -> 184.21
A17: 19230403 | F17: 48328 | G17: 45659 | H17: 45659 | I17: 420 | J17: OK | L17: LANÇADO | M17: 45659 | N17: =Tabela13891011121314[[#This Row],[Valor recibo]] -> 420
A18: 19207019 | F18: 48362 | G18: 45659 | H18: 45659 | I18: 1589.84 | J18: OK | L18: LANÇADO | M18: 45660 | N18: =Tabela13891011121314[[#This Row],[Valor recibo]] -> 1589.84
A19: 19223318 | F19: 48313/48314/48304 | G19: 45659 | H19: 45659 | I19: 206.5 | J19: OK | L19: LANÇADO | M19: 45660 | N19: =Tabela13891011121314[[#This Row],[Valor recibo]] -> 206.5
A20: 19230402 | F20: 48257 | G20: 45659 | H20: 45659 | I20: 420 | J20: OK | L20: LANÇADO | M20: 45660 | N20: =Tabela13891011121314[[#This Row],[Valor recibo]] -> 420
A21: 19206416 | F21: 47986 | G21: 45656 | H21: 45656 | I21: 1492.94 | J21: OK | L21: LANÇADO | M21: 45660 | N21: =Tabela13891011121314[[#This Row],[Valor recibo]] -> 1492.94
A22: 19224462 | F22: 48275/277/266/278/276/270/274/271/265/273/272 | G22: 45657 | H22: 45657 | I22: 1021 | J22: OK | L22: LANÇADO | M22: 45660 | N22: =Tabela13891011121314[[#This Row],[Valor recibo]] -> 1021
A23: 19219239 | F23: 48448/48449 | G23: 45657 | H23: 45657 | I23: 0 | J23: OK | N23: =Tabela13891011121314[[#This Row],[Valor recibo]] -> 0
A24: 19230401 | F24: 48251/48252 | G24: 45660 | H24: 45659 | I24: 420 | J24: OK | L24: LANÇADO | M24: 45660 | N24: =Tabela13891011121314[[#This Row],[Valor recibo]] -> 420
A25: 19223307 | F25: 48202/48203/48204/48201 | G25: 45659 | H25: 45659 | I25: 420 | J25: OK | L25: LANÇADO | M25: 45660 | N25: =Tabela13891011121314[[#This Row],[Valor recibo]] -> 420
A26: 19223297 | F26: 48397 | G26: 45659 | H26: 45659 | I26: 195 | J26: OK | L26: LANÇADO | M26: 45660 | N26: =Tabela13891011121314[[#This Row],[Valor recibo]] -> 195
A27: 19223329 | F27: 48336 | G27: 45659 | H27: 45659 | I27: 210 | J27: OK | L27: LANÇADO | M27: 45660 | N27: =Tabela13891011121314[[#This Row],[Valor recibo]] -> 210
A28: 19230280 | F28: 48294/48300/48299/48301/48302 | G28: 45659 | H28: 45659 | I28: 238 | J28: OK | L28: LANÇADO | M28: 45660 | N28: =Tabela13891011121314[[#This Row],[Valor recibo]] -> 238
A29: 19207712 | F29: 47800 | G29: 45687 | H29: 45687 | I29: 210 | J29: OK | L29: LANÇADO | M29: 45660 | N29: =Tabela13891011121314[[#This Row],[Valor recibo]] -> 210
A30: 19247451 | F30: 48351/48353/48354/48355/356/357/358 | G30: 45659 | H30: 45659 | I30: 238 | J30: OK | L30: LANÇADO | M30: 45660 | N30: =Tabela13891011121314[[#This Row],[Valor recibo]] -> 238
A31: 19228719 | F31: 48317/48320 | G31: 45659 | H31: 45659 | I31: 476 | J31: OK | L31: LANÇADO | M31: 45660 | N31: =Tabela13891011121314[[#This Row],[Valor recibo]] -> 476
A32: 19233705 | F32: 48368/48363/48366/48367/48369 | G32: 45659 | H32: 45659 | I32: 221 | J32: OK | L32: LANÇADO | M32: 45660 | N32: =Tabela13891011121314[[#This Row],[Valor recibo]] -> 221
A33: 19248511 | F33: 48760//48761 | G33: 45660 | H33: 45660 | I33: 560 | J33: OK | L33: LANÇADO | M33: 45660 | N33: =Tabela13891011121314[[#This Row],[Valor recibo]] -> 560
A34: 19250733 | F34: 48777/48775/48774/48776 | G34: 45660 | H34: 45660 | I34: 730 | J34: OK | L34: LANÇADO | M34: 45660 | N34: =Tabela13891011121314[[#This Row],[Valor recibo]] -> 730
A35: 19184590 | F35: 48246/48245 | G35: 45659 | H35: 45659 | I35: 531.6 | J35: OK | L35: LANÇADO | M35: 45660 | N35: =Tabela13891011121314[[#This Row],[Valor recibo]] -> 531.6
A36: 19233774 | F36: 48778/48780/48779 | G36: 45660 | H36: 45660 | I36: 357 | J36: OK | L36: LANÇADO | M36: 45660 | N36: =Tabela13891011121314[[#This Row],[Valor recibo]] -> 357
A37: 19172777 | F37: 47010 | G37: 45660 | H37: 45660 | I37: 588.4 | J37: OK | L37: LANÇADO | M37: 45660 | N37: =Tabela13891011121314[[#This Row],[Valor recibo]] -> 588.4
A38: 19230384 | F38: 48384/48381/48382/48383 | G38: 45660 | H38: 45660 | I38: 0 | N38: =Tabela13891011121314[[#This Row],[Valor recibo]] -> 0
A39: 19248434 | F39: 48746/48747 | G39: 45660 | H39: 45660 | I39: 584.4 | J39: OK | L39: LANÇADO | M39: 45660 | N39: =Tabela13891011121314[[#This Row],[Valor recibo]] -> 584.4
A40: 19210916 | F40: 47616/47614 | G40: 45661 | H40: 45661 | I40: 476 | J40: OK | L40: LANÇADO | M40: 45663 | N40: =Tabela13891011121314[[#This Row],[Valor recibo]] -> 476
...

Sheet MAIO
N1: =SUBTOTAL(9,Tabela1345[Match_Planilha]) -> 0 | O1: =SUBTOTAL(9,O3:O654) -> 0
A2: DT | B2: Data coleta | C2: Motorista | D2: Cliente/Fornecedor | E2: Local | F2: Numero NF | G2: Data canhoto | H2: Data recibo | I2: Valor recibo | J2: Scaner | K2: Drive-ANEXO | L2: status forms | M2: Data lançamento | N2: Match_Planilha | O2: Dif | P2: obs
O648: =IFERROR(IF(L648="PENDENTE",-N648,I648-N648),0) -> 0
O649: =IFERROR(IF(L649="PENDENTE",-N649,I649-N649),0) -> 0
O650: =IFERROR(IF(L650="PENDENTE",-N650,I650-N650),0) -> 0
O651: =IFERROR(IF(L651="PENDENTE",-N651,I651-N651),0) -> 0
O652: =IFERROR(IF(L652="PENDENTE",-N652,I652-N652),0) -> 0
O653: =IFERROR(IF(L653="PENDENTE",-N653,I653-N653),0) -> 0
O654: =IFERROR(IF(L654="PENDENTE",-N654,I654-N654),0) -> 0

Sheet JUNHO
N1: =SUBTOTAL(9,Tabela13456[Match_Planilha]) -> 0 | O1: =SUBTOTAL(9,O3:O584) -> 0
A2: DT | B2: Data coleta | C2: Motorista | D2: Cliente/Fornecedor | E2: Local | F2: Numero NF | G2: Data canhoto | H2: Data recibo | I2: Valor recibo | J2: Scaner | K2: Drive-ANEXO | L2: status forms | M2: Data lançamento | N2: Match_Planilha | O2: Dif | P2: obs
O577: =IFERROR(I577-N577,0) -> 0
O578: =IFERROR(I578-N578,0) -> 0
O579: =IFERROR(I579-N579,0) -> 0
O580: =IFERROR(I580-N580,0) -> 0
O581: =IFERROR(I581-N581,0) -> 0
O582: =IFERROR(I582-N582,0) -> 0
O583: =IFERROR(I583-N583,0) -> 0
O584: =IFERROR(I584-N584,0) -> 0
A586: =IF(N586="","",N586)

Sheet JULHO
N1: =SUBTOTAL(9,Tabela138[Match_Planilha]) -> 0 | O1: =SUBTOTAL(9,O3:O606) -> 0
A2: DT | B2: Data coleta | C2: Motorista | D2: Cliente/Fornecedor | E2: Local | F2: Numero NF | G2: Data canhoto | H2: Data recibo | I2: Valor recibo | J2: Scaner | K2: Drive-ANEXO | L2: status forms | M2: DATA LANÇAMENTO | N2: Match_Planilha | O2: Dif | P2: obs
A3: 18031736 | B3: 45474 | C3: MARCOS CECILIO DE OLIVEIRA | O3: =IFERROR(I3-N3,0) -> 0
A4: 18046422 | B4: 45474 | C4: AROLDO VICENTE CORDEIRO | O4: =IFERROR(I4-N4,0) -> 0
A5: 18046433 | B5: 45474 | C5: RODRIGO NOGUEIRA | O5: =IFERROR(I5-N5,0) -> 0
A6: 18037660 | B6: 45474 | C6: WILSON MOREIRA DE GODOY | O6: =IFERROR(I6-N6,0) -> 0
A7: 18046437 | B7: 45474 | C7: MARIO ADRIANO SILVA | O7: =IFERROR(I7-N7,0) -> 0
A8: 18040209 | B8: 45474 | C8: CLAUDIO JOSE FERREIRA JUNIOR | O8: =IFERROR(I8-N8,0) -> 0
C581: =IF(#REF!="","",VLOOKUP(#REF!,'[1]Ativos Agregados'!#REF!,2,0)) -> #REF! | O581: =IFERROR(I581-N581,0) -> 0
C582: =IF(#REF!="","",VLOOKUP(#REF!,'[1]Ativos Agregados'!#REF!,2,0)) -> #REF! | O582: =IFERROR(I582-N582,0) -> 0
C583: =IF(#REF!="","",VLOOKUP(#REF!,'[1]Ativos Agregados'!#REF!,2,0)) -> #REF! | O583: =IFERROR(I583-N583,0) -> 0
C584: =IF(#REF!="","",VLOOKUP(#REF!,'[1]Ativos Agregados'!#REF!,2,0)) -> #REF! | O584: =IFERROR(I584-N584,0) -> 0
C585: =IF(#REF!="","",VLOOKUP(#REF!,'[1]Ativos Agregados'!#REF!,2,0)) -> #REF! | O585: =IFERROR(I585-N585,0) -> 0
C586: =IF(#REF!="","",VLOOKUP(#REF!,'[1]Ativos Agregados'!#REF!,2,0)) -> #REF! | O586: =IFERROR(I586-N586,0) -> 0
C587: =IF(#REF!="","",VLOOKUP(#REF!,'[1]Ativos Agregados'!#REF!,2,0)) -> #REF! | O587: =IFERROR(I587-N587,0) -> 0
C588: =IF(#REF!="","",VLOOKUP(#REF!,'[1]Ativos Agregados'!#REF!,2,0)) -> #REF! | O588: =IFERROR(I588-N588,0) -> 0
C589: =IF(#REF!="","",VLOOKUP(#REF!,'[1]Ativos Agregados'!#REF!,2,0)) -> #REF! | O589: =IFERROR(I589-N589,0) -> 0
C590: =IF(#REF!="","",VLOOKUP(#REF!,'[1]Ativos Agregados'!#REF!,2,0)) -> #REF! | O590: =IFERROR(I590-N590,0) -> 0
C591: =IF(#REF!="","",VLOOKUP(#REF!,'[1]Ativos Agregados'!#REF!,2,0)) -> #REF! | O591: =IFERROR(I591-N591,0) -> 0
C592: =IF(#REF!="","",VLOOKUP(#REF!,'[1]Ativos Agregados'!#REF!,2,0)) -> #REF! | O592: =IFERROR(I592-N592,0) -> 0
... C606: =IF(#REF!="","",VLOOKUP(#REF!,'[1]Ativos Agregados'!#REF!,2,0)) -> #REF! | O606: =IFERROR(I606-N606,0) -> 0

Sheet AGOSTO
N1: =SUBTOTAL(9,Tabela1389[Match_Planilha]) -> 0 | O1: =SUBTOTAL(9,O3:O604) -> 0
A2: DT | B2: Data coleta | C2: Motorista | D2: Cliente/Fornecedor | E2: Local | F2: Numero NF | G2: Data canhoto | H2: Data recibo | I2: Valor recibo | J2: Scaner | K2: Drive-ANEXO | L2: status forms | M2: DATA LANÇAMENTO | N2: Match_Planilha | O2: Dif | P2: obs

Sheet SETEMBRO
N1: =SUBTOTAL(9,Tabela138910[Match_Planilha]) -> 0 | O1: =SUBTOTAL(9,O3:O603) -> 0
A2: DT | B2: Data coleta | C2: Motorista | D2: Cliente/Fornecedor | E2: Local | F2: Numero NF | G2: Data canhoto | H2: Data recibo | I2: Valor recibo | J2: Scaner | K2: Drive-ANEXO | L2: status forms | M2: DATA LANÇAMENTO | N2: Match_Planilha | O2: Dif | P2: obs

Sheet OUTUBRO
N1: =SUBTOTAL(9,Tabela13891011[Match_Planilha]) -> 0 | O1: =SUBTOTAL(9,Tabela13891011[Dif]) -> 0
A2: DT | B2: Data coleta | C2: Motorista | D2: Cliente/Fornecedor | E2: Local | F2: Numero NF | G2: Data canhoto | H2: Data recibo | I2: Valor recibo | J2: Scaner | K2: Drive-ANEXO | L2: status forms | M2: DATA LANÇAMENTO | N2: Match_Planilha | O2: Dif | P2: obs
J600: OK | L600: LANÇADO

Sheet NOVEMBRO
N1: =SUBTOTAL(9,Tabela1389101112[Match_Planilha]) -> 0 | O1: =SUBTOTAL(9,Tabela1389101112[Dif]) -> 0
A2: DT | B2: Data coleta | C2: Motorista | D2: Cliente/Fornecedor | E2: Local | F2: Numero NF | G2: Data canhoto | H2: Data recibo | I2: Valor recibo | J2: Scaner | K2: Drive-ANEXO | L2: status forms | M2: DATA LANÇAMENTO | N2: Match_Planilha | O2: Dif | P2: obs

Sheet DEZEMBRO
N1: =SUBTOTAL(9,Tabela138910111213[Match_Planilha]) -> 0 | O1: =SUBTOTAL(9,Tabela138910111213[Dif]) -> 0
A2: DT | B2: Data coleta | C2: Motorista | D2: Cliente/Fornecedor | E2: Local | F2: Numero NF | G2: Data canhoto | H2: Data recibo | I2: Valor recibo | J2: Scaner | K2: Drive-ANEXO | L2: status forms | M2: DATA LANÇAMENTO | N2: Match_Planilha | O2: Dif | P2: obs
L440: PENDENTE | N440: =Tabela138910111213[[#This Row],[Valor recibo]] -> 0

Sheet FEVEREIRO 2025
N1: =SUBTOTAL(9,Tabela1389101112131415[Match_Planilha]) -> 33625.45 | O1: =SUBTOTAL(9,Tabela1389101112131415[Dif]) -> 0
A2: DT | B2: Data coleta | C2: Motorista | D2: Cliente/Fornecedor | E2: Local | F2: Numero NF | G2: Data canhoto | H2: Data recibo | I2: Valor recibo | J2: Scaner | K2: Drive-ANEXO | L2: status forms | M2: DATA LANÇAMENTO | N2: Match_Planilha | O2: Dif | P2: obs
A3: 19450071 | F3: 53239 | G3: 45691 | H3: 45691 | I3: 0 | J3: OK | L3: LANÇADO | M3: 45691 | N3: =Tabela1389101112131415[[#This Row],[Valor recibo]] -> 0 | P3: COMPROVEI OK
A4: 19390987 | F4: 51778 | G4: 45681 | H4: 45712 | I4: 532 | J4: OK | L4: LANÇADO | M4: 45691 | N4: =Tabela1389101112131415[[#This Row],[Valor recibo]] -> 532 | P4: COMPROVEI OK
A5: 19443170 | F5: 52908 | G5: 45688 | H5: 45688 | I5: 476 | J5: OK | L5: LANÇADO | M5: 45691 | N5: =Tabela1389101112131415[[#This Row],[Valor recibo]] -> 476 | P5: COMPROVEI OK
A6: 19441830 | F6: 53401/53284 | G6: 45691 | H6: 45691 | I6: 442 | J6: OK | L6: LANÇADO | M6: 45691 | N6: =Tabela1389101112131415[[#This Row],[Valor recibo]] -> 442 | P6: COMPROVEI OK
A7: 19448927 | F7: 53238 | G7: 45689 | H7: 45689 | I7: 476 | J7: OK | L7: LANÇADO | M7: 45691 | N7: =Tabela1389101112131415[[#This Row],[Valor recibo]] -> 476 | P7: COMPROVEI OK
A8: 19443972 | F8: 24714/24715/24713/24716 | G8: 45688 | H8: 45688 | I8: 1645 | J8: OK | L8: LANÇADO | M8: 45691 | N8: =Tabela1389101112131415[[#This Row],[Valor recibo]] -> 1645 | P8: COMPROVEI OK
A9: 19405481 | F9: 53231 | G9: 45689 | H9: 45689 | I9: 0 | J9: OK | L9: LANÇADO | M9: 45691 | N9: =Tabela1389101112131415[[#This Row],[Valor recibo]] -> 0 | P9: COMPROVEI OK
A10: 19427603 | F10: 52432/52431 | G10: 45686 | H10: 45686 | I10: 476 | J10: OK | L10: LANÇADO | M10: 45691 | N10: =Tabela1389101112131415[[#This Row],[Valor recibo]] -> 476 | P10: COMPROVEI OK
A11: 19429660 | F11: 52983 | G11: 45688 | H11: 45688 | I11: 476 | J11: OK | L11: LANÇADO | M11: 45691 | N11: =Tabela1389101112131415[[#This Row],[Valor recibo]] -> 476 | P11: COMPROVEI OK
A12: 19434342 | F12: 52962/52961/52969 | G12: 45688 | H12: 45688 | I12: 238 | J12: OK | L12: LANÇADO | M12: 45691 | N12: =Tabela1389101112131415[[#This Row],[Valor recibo]] -> 238 | P12: COMPROVEI OK
A13: 19432719 | F13: 52822 | G13: 45688 | H13: 45688 | I13: 1485.8 | J13: OK | L13: LANÇADO | M13: 45691 | N13: =Tabela1389101112131415[[#This Row],[Valor recibo]] -> 1485.8 | P13: COMPROVEI OK
A14: 19432500 | F14: 53026 | G14: 45688 | H14: 45688 | I14: 420 | J14: OK | L14: LANÇADO | M14: 45691 | N14: =Tabela1389101112131415[[#This Row],[Valor recibo]] -> 420 | P14: COMPROVEI OK
A15: 19444201 | F15: 24781 | G15: 45688 | H15: 45688 | I15: 489 | J15: OK | L15: LANÇADO | M15: 45691 | N15: =Tabela1389101112131415[[#This Row],[Valor recibo]] -> 489 | P15: COMPROVEI OK
A16: 19444686 | F16: 52843 | G16: 45688 | H16: 45688 | I16: 476 | J16: OK | L16: LANÇADO | M16: 45691 | N16: =Tabela1389101112131415[[#This Row],[Valor recibo]] -> 476 | P16: COMPROVEI OK
A17: 19442074 | F17: 53046 | G17: 45688 | H17: 45688 | I17: 476 | J17: OK | L17: LANÇADO | M17: 45691 | N17: =Tabela1389101112131415[[#This Row],[Valor recibo]] -> 476 | P17: COMPROVEI OK
A18: 19444707 | F18: 53233 | G18: 45689 | H18: 45689 | I18: 476 | J18: OK | L18: LANÇADO | M18: 45691 | N18: =Tabela1389101112131415[[#This Row],[Valor recibo]] -> 476 | P18: COMPROVEI OK
A19: 19448928 | F19: 53256 | G19: 45689 | H19: 45689 | I19: 476 | J19: OK | L19: LANÇADO | M19: 45691 | N19: =Tabela1389101112131415[[#This Row],[Valor recibo]] -> 476 | P19: COMPROVEI OK
A20: 19429669 | F20: 52861 | G20: 45688 | H20: 45688 | I20: 476 | J20: OK | L20: LANÇADO | M20: 45691 | N20: =Tabela1389101112131415[[#This Row],[Valor recibo]] -> 476 | P20: PENDENTE
A21: 19444202 | F21: 24763 | G21: 45689 | H21: 45689 | I21: 864 | J21: OK | L21: LANÇADO | M21: 45691 | N21: =Tabela1389101112131415[[#This Row],[Valor recibo]] -> 864 | P21: COMPROVEI OK
A22: 19449915 | F22: 53252 | G22: 45689 | H22: 45689 | I22: 0 | J22: OK | L22: LANÇADO | M22: 45691 | N22: =Tabela1389101112131415[[#This Row],[Valor recibo]] -> 0 | P22: COMPROVEI OK
A23: 19449912 | F23: 53242/53243 | G23: 45689 | H23: 45689 | I23: 0 | J23: OK | L23: LANÇADO | M23: 45691 | N23: =Tabela1389101112131415[[#This Row],[Valor recibo]] -> 0 | P23: COMPROVEI OK
A24: 19448925 | F24: 53235 | G24: 45689 | H24: 45689 | I24: 476 | J24: OK | L24: LANÇADO | M24: 45691 | N24: =Tabela1389101112131415[[#This Row],[Valor recibo]] -> 476 | P24: COMPROVEI OK
A25: 19429396 | F25: 53453/53443 | G25: 45691 | H25: 45691 | I25: 476 | J25: OK | L25: LANÇADO | M25: 45691 | N25: =Tabela1389101112131415[[#This Row],[Valor recibo]] -> 476 | P25: COMPROVEI OK
A26: 19405482 | F26: 53419/53412 | G26: 45691 | H26: 45691 | I26: 0 | J26: OK | L26: LANÇADO | M26: 45691 | N26: =Tabela1389101112131415[[#This Row],[Valor recibo]] -> 0 | P26: COMPROVEI OK
A27: 19436253 | F27: 53266/53265/53386 | G27: 45691 | H27: 45691 | I27: 238 | J27: OK | L27: LANÇADO | M27: 45691 | N27: =Tabela1389101112131415[[#This Row],[Valor recibo]] -> 238 | P27: COMPROVEI OK
A28: 19443508 | F28: 52972/52973/52971 | G28: 45688 | H28: 45688 | I28: 1687.5 | J28: OK | L28: LANÇADO | M28: 45691 | N28: =Tabela1389101112131415[[#This Row],[Valor recibo]] -> 1687.5 | P28: COMPROVEI OK
A29: 19444455 | F29: 53496/53495 | G29: 45691 | H29: 45691 | I29: 476 | J29: OK | L29: LANÇADO | M29: 45691 | N29: =Tabela1389101112131415[[#This Row],[Valor recibo]] -> 476 | P29: PENDENTE
A30: 19427692 | F30: 53364/53410/53363 | G30: 45691 | H30: 45691 | I30: 476 | J30: OK | L30: LANÇADO | M30: 45691 | N30: =Tabela1389101112131415[[#This Row],[Valor recibo]] -> 476 | P30: COMPROVEI OK
A31: 19444452 | F31: 53437/53436 | G31: 45691 | H31: 45691 | I31: 476 | J31: OK | L31: LANÇADO | M31: 45691 | N31: =Tabela1389101112131415[[#This Row],[Valor recibo]] -> 476 | P31: COMPROVEI OK
A32: 19428102 | F32: 53483/53482/53484 | G32: 45691 | H32: 45691 | I32: 476 | J32: OK | L32: LANÇADO | M32: 45692 | N32: =Tabela1389101112131415[[#This Row],[Valor recibo]] -> 476 | P32: COMPROVEI OK
A33: 19444451 | F33: 53485/53486 | G33: 45692 | H33: 45692 | I33: 442 | J33: OK | L33: LANÇADO | M33: 45692 | N33: =Tabela1389101112131415[[#This Row],[Valor recibo]] -> 442 | P33: COMPROVEI OK
A34: 19429401 | F34: 53589/53588 | G34: 45692 | H34: 45692 | I34: 476 | J34: OK | L34: LANÇADO | M34: 45692 | N34: =Tabela1389101112131415[[#This Row],[Valor recibo]] -> 476 | P34: COMPROVEI OK
A35: 19433642 | F35: 52736/52734 | G35: 45687 | H35: 45687 | I35: 238 | J35: OK | L35: LANÇADO | M35: 45692 | N35: =Tabela1389101112131415[[#This Row],[Valor recibo]] -> 238 | P35: COMPROVEI OK
A36: 19429636 | F36: 53301/53234 | G36: 45691 | H36: 45691 | I36: 238 | J36: OK | L36: LANÇADO | M36: 45692 | N36: =Tabela1389101112131415[[#This Row],[Valor recibo]] -> 238 | P36: COMPROVEI OK
A37: 19409127 | F37: 52409 | G37: 45686 | H37: 45686 | I37: 221 | J37: OK | L37: LANÇADO | M37: 45692 | N37: =Tabela1389101112131415[[#This Row],[Valor recibo]] -> 221 | P37: COMPROVEI OK
A38: 19441831 | F38: 53286/53395 | G38: 45691 | H38: 45691 | I38: 476 | J38: OK | L38: LANÇADO | M38: 45692 | N38: =Tabela1389101112131415[[#This Row],[Valor recibo]] -> 476 | P38: COMPROVEI OK
A39: 19448912 | F39: 53494/53493 | G39: 45691 | H39: 45691 | I39: 476 | J39: OK | L39: LANÇADO | M39: 45692 | N39: =Tabela1389101112131415[[#This Row],[Valor recibo]] -> 476 | P39: COMPROVEI OK
A40: 19445107 | F40: 24855 | G40: 45691 | H40: 45691 | I40: 1680 | J40: OK | L40: LANÇADO | M40: 45692 | N40: =Tabela1389101112131415[[#This Row],[Valor recibo]] -> 1680 | P40: COMPROVEI OK
...

Sheet JANEIRO 2026
A1: forms | D1: forms | E1: forms | K1: =SUBTOTAL(9,Tabela1316[Valor_recibo]) -> 35163.73 | M1: =SUBTOTAL(9,Tabela1316[Valor_recibo]) -> 35163.73 | P1: =SUBTOTAL(9,Tabela1316[Match_Planilha]) -> 33659.73 | Q1: =SUBTOTAL(9,Q3:Q559) -> 0 | T1: =SUBTOTAL(9,T3:T194) -> 0 | U1: PEDAGIO | X1: forms
A2: DT | B2: Data coleta | C2: Motorista | D2: VEICULO | E2: EIXO | F2: Cliente/Fornecedor | G2: Local | H2: Numero NF | I2: Data canhoto | J2: Data recibo | K2: Valor_recibo | L2: Scaner | M2: APROVAÇÃO_SUZANO | N2: status forms | O2: Data lançamento | P2: Match_Planilha | Q2: Dif | R2: DTS APROVADAS | S2: CTE COMPLEMENTAR | T2: VALOR | U2: STATUS REC CLIENTE | V2: DATA LANÇAMENTO2 | W2: Forms Pedagio | X2: valor | Y2: Data lançamento | Z2: obs
A3: 22215673 | B3: 46024 | C3: SEVERINO JOSE DA SILVA | D3: =VLOOKUP(Tabela1316[[#This Row],[Motorista]],Planilha1!A:C,3,0) -> CARRETA | E3: =IF(Tabela1316[[#This Row],[VEICULO]]="CARRETA",5,IF(Tabela1316[[#This Row],[VEICULO]]="TRUCK BAU",3,0)) -> 5 | G3: CAJAMAR | H3: 150151 | I3: 46034 | J3: 46034 | K3: 532 | L3: OK | M3: PENDENTE | N3: LANÇADO | O3: 46036 | P3: =Tabela1316[[#This Row],[Valor_recibo]] -> 532 | R3: =VLOOKUP(#REF!,[2]Aprovados!A:A,1,0) -> #REF! | U3: PENDENTE | W3: LANÇADO | X3: 289.5 | Y3: 46024
A4: 22215879 | B4: 46024 | C4: LEONARDO BADESKI | D4: =VLOOKUP(Tabela1316[[#This Row],[Motorista]],Planilha1!A:C,3,0) -> CARRETA | E4: =IF(Tabela1316[[#This Row],[VEICULO]]="CARRETA",5,IF(Tabela1316[[#This Row],[VEICULO]]="TRUCK BAU",3,0)) -> 5 | G4: CAJAMAR | H4: 150333 | I4: 46025 | J4: 46025 | K4: 532 | L4: OK | M4: PENDENTE | N4: LANÇADO | O4: 46029 | P4: =Tabela1316[[#This Row],[Valor_recibo]] -> 532 | R4: =VLOOKUP(#REF!,[2]Aprovados!A:A,1,0) -> #REF! | U4: PENDENTE | W4: LANÇADO | X4: 289.5 | Y4: 46024
A5: 22219964 | B5: 46024 | C5: MARIO ADRIANO SILVA | D5: =VLOOKUP(Tabela1316[[#This Row],[Motorista]],Planilha1!A:C,3,0) -> CARRETA | E5: =IF(Tabela1316[[#This Row],[VEICULO]]="CARRETA",5,IF(Tabela1316[[#This Row],[VEICULO]]="TRUCK BAU",3,0)) -> 5 | G5: SUMARE | H5: 150155/150156/150157/150158/150159/150160/150161/150162/150163/150164/150165/150166/150167 | I5: 46025 | J5: 46025 | K5: 2000 | L5: OK | M5: PENDENTE | N5: LANÇADO | O5: 46029 | P5: =Tabela1316[[#This Row],[Valor_recibo]] -> 2000 | R5: =VLOOKUP(#REF!,[2]Aprovados!A:A,1,0) -> #REF! | U5: PENDENTE | W5: LANÇADO | X5: 331.5 | Y5: 46024
A6: 22215635 | B6: 46024 | C6: LOURENÇO MALAFAIA | D6: =VLOOKUP(Tabela1316[[#This Row],[Motorista]],Planilha1!A:C,3,0) -> CARRETA | E6: =IF(Tabela1316[[#This Row],[VEICULO]]="CARRETA",5,IF(Tabela1316[[#This Row],[VEICULO]]="TRUCK BAU",3,0)) -> 5 | G6: CAJAMAR | H6: 52171 | I6: 46025 | J6: 46025 | K6: 532 | L6: OK | M6: PENDENTE | N6: LANÇADO | O6: 46029 | P6: =Tabela1316[[#This Row],[Valor_recibo]] -> 532 | R6: =VLOOKUP(#REF!,[2]Aprovados!A:A,1,0) -> #REF! | U6: PENDENTE | W6: LANÇADO | X6: 289.5 | Y6: 46024
A7: 22248452 | B7: 46024 | C7: DANILO JUSTINO MENDES | D7: =VLOOKUP(Tabela1316[[#This Row],[Motorista]],Planilha1!A:C,3,0) -> TRUCK BAU | E7: =IF(Tabela1316[[#This Row],[VEICULO]]="CARRETA",5,IF(Tabela1316[[#This Row],[VEICULO]]="TRUCK BAU",3,0)) -> 3 | G7: SAO PAULO | H7: 151060/151061/151062/151063/151064/151065 | I7: 46028 | J7: 46028 | K7: 199.07 | L7: OK | M7: PENDENTE | N7: LANÇADO | O7: 46034 | P7: =Tabela1316[[#This Row],[Valor_recibo]] -> 199.07 | R7: =VLOOKUP(#REF!,[2]Aprovados!A:A,1,0) -> #REF! | U7: PENDENTE | W7: LANÇADO | X7: 47.4 | Y7: 46024
A8: 22226880 | B8: 46024 | C8: IVAN RODRIGUES | D8: =VLOOKUP(Tabela1316[[#This Row],[Motorista]],Planilha1!A:C,3,0) -> CARRETA | E8: =IF(Tabela1316[[#This Row],[VEICULO]]="CARRETA",5,IF(Tabela1316[[#This Row],[VEICULO]]="TRUCK BAU",3,0)) -> 5 | G8: MOGI DAS CRUZES | M8: PENDENTE | N8: PENDENTE | P8: =Tabela1316[[#This Row],[Valor_recibo]] -> 0 | R8: =VLOOKUP(#REF!,[2]Aprovados!A:A,1,0) -> #REF! | U8: PENDENTE | W8: LANÇADO | X8: 70.74 | Y8: 46024
A9: 22205018 | B9: 46025 | C9: EVANDRO DE ROSSI | D9: =VLOOKUP(Tabela1316[[#This Row],[Motorista]],Planilha1!A:C,3,0) -> CARRETA | E9: =IF(Tabela1316[[#This Row],[VEICULO]]="CARRETA",5,IF(Tabela1316[[#This Row],[VEICULO]]="TRUCK BAU",3,0)) -> 5 | G9: CAJAMAR | H9: 148773/148774/148775 | I9: 46026 | J9: 46026 | K9: 0 | L9: OK | O9: 46029 | P9: =Tabela1316[[#This Row],[Valor_recibo]] -> 0 | R9: =VLOOKUP(#REF!,[2]Aprovados!A:A,1,0) -> #REF! | U9: PENDENTE | W9: LANÇADO | X9: 289.5 | Y9: 46024
A10: 22248916 | B10: 46026 | C10: JOSE CICERO | D10: =VLOOKUP(Tabela1316[[#This Row],[Motorista]],Planilha1!A:C,3,0) -> CARRETA | E10: =IF(Tabela1316[[#This Row],[VEICULO]]="CARRETA",5,IF(Tabela1316[[#This Row],[VEICULO]]="TRUCK BAU",3,0)) -> 5 | G10: SANTA BARBARA | H10: 150462/140542 | I10: 46026 | J10: 46026 | K10: 420 | L10: OK | M10: PENDENTE | N10: LANÇADO | O10: 46036 | P10: =Tabela1316[[#This Row],[Valor_recibo]] -> 420 | R10: =VLOOKUP(#REF!,[2]Aprovados!A:A,1,0) -> #REF! | U10: PENDENTE | W10: LANÇADO | X10: 445.5 | Y10: 46027
A11: 22247568 | B11: 46026 | C11: EMERSON RABELO DIAS | D11: =VLOOKUP(Tabela1316[[#This Row],[Motorista]],Planilha1!A:C,3,0) -> TRUCK BAU | E11: =IF(Tabela1316[[#This Row],[VEICULO]]="CARRETA",5,IF(Tabela1316[[#This Row],[VEICULO]]="TRUCK BAU",3,0)) -> 3 | G11: SAO PAULO | H11: 151043/151042/151041/151040/151039 | I11: 46027 | J11: 46027 | K11: 227.23 | L11: OK | M11: PENDENTE | N11: LANÇADO | O11: 46029 | P11: =Tabela1316[[#This Row],[Valor_recibo]] -> 227.23 | R11: =VLOOKUP(#REF!,[2]Aprovados!A:A,1,0) -> #REF! | U11: PENDENTE | W11: LANÇADO | X11: 47.4 | Y11: 46027
A12: 22259442 | B12: 46026 | C12: JACKSON MARCELINO | D12: =VLOOKUP(Tabela1316[[#This Row],[Motorista]],Planilha1!A:C,3,0) -> CARRETA | E12: =IF(Tabela1316[[#This Row],[VEICULO]]="CARRETA",5,IF(Tabela1316[[#This Row],[VEICULO]]="TRUCK BAU",3,0)) -> 5 | G12: BARUERI | H12: 151047 | I12: 46027 | J12: 46027 | K12: 0 | L12: OK | M12: PENDENTE | O12: 46029 | P12: =Tabela1316[[#This Row],[Valor_recibo]] -> 0 | R12: =VLOOKUP(#REF!,[2]Aprovados!A:A,1,0) -> #REF! | U12: PENDENTE | W12: LANÇADO | X12: 132.5 | Y12: 46027
A13: 22215240 | B13: 46027 | C13: ELTON MORGADO | D13: =VLOOKUP(Tabela1316[[#This Row],[Motorista]],Planilha1!A:C,3,0) -> TRUCK BAU | E13: =IF(Tabela1316[[#This Row],[VEICULO]]="CARRETA",5,IF(Tabela1316[[#This Row],[VEICULO]]="TRUCK BAU",3,0)) -> 3 | G13: SAO PAULO | H13: 151336/151335 | I13: 46028 | J13: 46028 | K13: 204 | L13: OK | M13: PENDENTE | N13: LANÇADO | O13: 46030 | P13: =Tabela1316[[#This Row],[Valor_recibo]] -> 204 | R13: =VLOOKUP(#REF!,[2]Aprovados!A:A,1,0) -> #REF! | U13: PENDENTE | W13: LANÇADO | X13: 47.4 | Y13: 46028
A14: 22248445 | B14: 46027 | C14: EMERSON RABELO DIAS | D14: =VLOOKUP(Tabela1316[[#This Row],[Motorista]],Planilha1!A:C,3,0) -> TRUCK BAU | E14: =IF(Tabela1316[[#This Row],[VEICULO]]="CARRETA",5,IF(Tabela1316[[#This Row],[VEICULO]]="TRUCK BAU",3,0)) -> 3 | G14: ITAQUAQUECETUBA | H14: 151391/151392/151393 | I14: 46028 | J14: 46028 | K14: 238 | L14: OK | M14: PENDENTE | N14: LANÇADO | O14: 46036 | P14: =Tabela1316[[#This Row],[Valor_recibo]] -> 238 | R14: =VLOOKUP(#REF!,[2]Aprovados!A:A,1,0) -> #REF! | U14: PENDENTE | W14: LANÇADO | X14: 25.8 | Y14: 46028
A15: 22257905 | B15: 46027 | C15: BRUNO FERREIRA OLIVEIRA | D15: =VLOOKUP(Tabela1316[[#This Row],[Motorista]],Planilha1!A:C,3,0) -> CARRETA | E15: =IF(Tabela1316[[#This Row],[VEICULO]]="CARRETA",5,IF(Tabela1316[[#This Row],[VEICULO]]="TRUCK BAU",3,0)) -> 5 | G15: CAJAMAR | H15: 150308 | I15: 46028 | J15: 46028 | K15: 750 | L15: OK | M15: PENDENTE | N15: LANÇADO | O15: 46037 | P15: =Tabela1316[[#This Row],[Valor_recibo]] -> 750 | R15: =VLOOKUP(#REF!,[2]Aprovados!A:A,1,0) -> #REF! | U15: PENDENTE | W15: LANÇADO | X15: 289.5 | Y15: 46028
A16: 22248657 | B16: 46027 | C16: SEVERINO JOSE DA SILVA | D16: =VLOOKUP(Tabela1316[[#This Row],[Motorista]],Planilha1!A:C,3,0) -> CARRETA | E16: =IF(Tabela1316[[#This Row],[VEICULO]]="CARRETA",5,IF(Tabela1316[[#This Row],[VEICULO]]="TRUCK BAU",3,0)) -> 5 | G16: CAJAMAR | H16: 1498122 | I16: 46028 | J16: 46028 | K16: 0 | M16: PENDENTE | O16: 46029 | P16: =Tabela1316[[#This Row],[Valor_recibo]] -> 0 | R16: =VLOOKUP(#REF!,[2]Aprovados!A:A,1,0) -> #REF! | U16: PENDENTE | W16: LANÇADO | X16: 289.5 | Y16: 46028
A17: 22248655 | B17: 46027 | C17: EVANDRO DE ROSSI | D17: =VLOOKUP(Tabela1316[[#This Row],[Motorista]],Planilha1!A:C,3,0) -> CARRETA | E17: =IF(Tabela1316[[#This Row],[VEICULO]]="CARRETA",5,IF(Tabela1316[[#This Row],[VEICULO]]="TRUCK BAU",3,0)) -> 5 | G17: CAJAMAR | H17: 149809 | I17: 46028 | J17: 46028 | K17: 0 | L17: OK | M17: PENDENTE | O17: 46034 | P17: =Tabela1316[[#This Row],[Valor_recibo]] -> 0 | R17: =VLOOKUP(#REF!,[2]Aprovados!A:A,1,0) -> #REF! | U17: PENDENTE | W17: LANÇADO | X17: 289.5 | Y17: 46028
A18: 22249304 | B18: 46027 | C18: MARIO ADRIANO SILVA | D18: =VLOOKUP(Tabela1316[[#This Row],[Motorista]],Planilha1!A:C,3,0) -> CARRETA | E18: =IF(Tabela1316[[#This Row],[VEICULO]]="CARRETA",5,IF(Tabela1316[[#This Row],[VEICULO]]="TRUCK BAU",3,0)) -> 5 | G18: SÃO VICENTE | H18: 151494/151495/151496/151497/151498/151499/151500 | I18: 46028 | J18: 46028 | K18: 476 | L18: OK | M18: PENDENTE | N18: LANÇADO | O18: 46030 | P18: =Tabela1316[[#This Row],[Valor_recibo]] -> 476 | R18: =VLOOKUP(#REF!,[2]Aprovados!A:A,1,0) -> #REF! | U18: PENDENTE | W18: LANÇADO | X18: 392.5 | Y18: 46028
A19: 22312814 | B19: 46027 | C19: LEONARDO BADESKI | D19: =VLOOKUP(Tabela1316[[#This Row],[Motorista]],Planilha1!A:C,3,0) -> CARRETA | E19: =IF(Tabela1316[[#This Row],[VEICULO]]="CARRETA",5,IF(Tabela1316[[#This Row],[VEICULO]]="TRUCK BAU",3,0)) -> 5 | G19: SÃO PAULO | H19: 151489 | I19: 46028 | J19: 46028 | K19: 340 | L19: OK | M19: PENDENTE | N19: LANÇADO | O19: 46029 | P19: =Tabela1316[[#This Row],[Valor_recibo]] -> 340 | R19: =VLOOKUP(#REF!,[2]Aprovados!A:A,1,0) -> #REF! | U19: PENDENTE | W19: LANÇADO | X19: 79 | Y19: 46028
A20: 22248431 | B20: 46028 | C20: WELLINGTON GODOY | D20: TRUCK BAU | E20: =IF(Tabela1316[[#This Row],[VEICULO]]="CARRETA",5,IF(Tabela1316[[#This Row],[VEICULO]]="TRUCK BAU",3,0)) -> 3 | G20: JACAREÍ | H20: 151665/151666/151667//151668/151669 | I20: 46029 | J20: 46029 | K20: 328 | L20: OK | M20: PENDENTE | N20: LANÇADO | O20: 46034 | P20: =Tabela1316[[#This Row],[Valor_recibo]] -> 328 | R20: =VLOOKUP(#REF!,[2]Aprovados!A:A,1,0) -> #REF! | U20: PENDENTE | W20: LANÇADO | X20: 89.7 | Y20: 46029
A21: 22248439 | B21: 46028 | C21: LEONARDO BADESKI | D21: =VLOOKUP(Tabela1316[[#This Row],[Motorista]],Planilha1!A:C,3,0) -> CARRETA | E21: =IF(Tabela1316[[#This Row],[VEICULO]]="CARRETA",5,IF(Tabela1316[[#This Row],[VEICULO]]="TRUCK BAU",3,0)) -> 5 | G21: JACAREI | H21: 151682 | I21: 46029 | J21: 46029 | K21: 476 | L21: OK | M21: PENDENTE | N21: LANÇADO | O21: 46030 | P21: =Tabela1316[[#This Row],[Valor_recibo]] -> 476 | R21: =VLOOKUP(#REF!,[2]Aprovados!A:A,1,0) -> #REF! | U21: PENDENTE | W21: LANÇADO | X21: 149.5 | Y21: 46029
A22: 22248658 | B22: 46028 | C22: LOURENÇO MALAFAIA | D22: =VLOOKUP(Tabela1316[[#This Row],[Motorista]],Planilha1!A:C,3,0) -> CARRETA | E22: =IF(Tabela1316[[#This Row],[VEICULO]]="CARRETA",5,IF(Tabela1316[[#This Row],[VEICULO]]="TRUCK BAU",3,0)) -> 5 | G22: CAJAMAR | H22: 149813 | I22: 46029 | J22: 46029 | K22: 0 | L22: OK | M22: PENDENTE | O22: 46034 | P22: =Tabela1316[[#This Row],[Valor_recibo]] -> 0 | R22: =VLOOKUP(#REF!,[2]Aprovados!A:A,1,0) -> #REF! | U22: PENDENTE | W22: LANÇADO | X22: 289.5 | Y22: 46029
A23: 22328980 | B23: 46028 | C23: THIAGO PANZELLI | D23: TRUCK BAU | E23: =IF(Tabela1316[[#This Row],[VEICULO]]="CARRETA",5,IF(Tabela1316[[#This Row],[VEICULO]]="TRUCK BAU",3,0)) -> 3 | G23: BARUERI | H23: 151617/151616 | I23: 46029 | J23: 46029 | K23: 0 | L23: OK | M23: PENDENTE | N23: LANÇADO | O23: 46034 | P23: =Tabela1316[[#This Row],[Valor_recibo]] -> 0 | R23: =VLOOKUP(#REF!,[2]Aprovados!A:A,1,0) -> #REF! | U23: PENDENTE | W23: LANÇADO | X23: 79.5 | Y23: 46029
A24: 22313564 | B24: 46028 | C24: SEVERINO JOSE DA SILVA | D24: =VLOOKUP(Tabela1316[[#This Row],[Motorista]],Planilha1!A:C,3,0) -> CARRETA | E24: =IF(Tabela1316[[#This Row],[VEICULO]]="CARRETA",5,IF(Tabela1316[[#This Row],[VEICULO]]="TRUCK BAU",3,0)) -> 5 | G24: CAJAMAR | H24: 151333 | I24: 46029 | J24: 46029 | K24: 0 | L24: OK | M24: PENDENTE | O24: 46036 | P24: =Tabela1316[[#This Row],[Valor_recibo]] -> 0 | R24: =VLOOKUP(#REF!,[2]Aprovados!A:A,1,0) -> #REF! | U24: PENDENTE | W24: LANÇADO | X24: 289.5 | Y24: 46029
A25: 22313561 | B25: 46029 | C25: BRUNO FERREIRA OLIVEIRA | D25: =VLOOKUP(Tabela1316[[#This Row],[Motorista]],Planilha1!A:C,3,0) -> CARRETA | E25: =IF(Tabela1316[[#This Row],[VEICULO]]="CARRETA",5,IF(Tabela1316[[#This Row],[VEICULO]]="TRUCK BAU",3,0)) -> 5 | G25: CAJAMAR | H25: 151331 | I25: 46030 | J25: 46030 | K25: 0 | L25: OK | M25: PENDENTE | O25: 46036 | P25: =Tabela1316[[#This Row],[Valor_recibo]] -> 0 | R25: =VLOOKUP(#REF!,[2]Aprovados!A:A,1,0) -> #REF! | U25: PENDENTE | W25: LANÇADO | X25: 289.5 | Y25: 46030
A26: 22313562 | B26: 46029 | C26: MARIO ADRIANO SILVA | D26: =VLOOKUP(Tabela1316[[#This Row],[Motorista]],Planilha1!A:C,3,0) -> CARRETA | E26: =IF(Tabela1316[[#This Row],[VEICULO]]="CARRETA",5,IF(Tabela1316[[#This Row],[VEICULO]]="TRUCK BAU",3,0)) -> 5 | G26: CAJAMAR | H26: 151332 | I26: 46030 | J26: 46030 | K26: 0 | L26: OK | M26: PENDENTE | N26: LANÇADO | O26: 46034 | P26: =Tabela1316[[#This Row],[Valor_recibo]] -> 0 | R26: =VLOOKUP(#REF!,[2]Aprovados!A:A,1,0) -> #REF! | U26: PENDENTE | W26: LANÇADO | X26: 289.5 | Y26: 46030
A27: 22152496 | B27: 46029 | C27: LEONARDO BADESKI | D27: =VLOOKUP(Tabela1316[[#This Row],[Motorista]],Planilha1!A:C,3,0) -> CARRETA | E27: =IF(Tabela1316[[#This Row],[VEICULO]]="CARRETA",5,IF(Tabela1316[[#This Row],[VEICULO]]="TRUCK BAU",3,0)) -> 5 | G27: OSASCO | H27: 146384/146383/146382 | I27: 46030 | J27: 46030 | K27: 238 | L27: OK | M27: PENDENTE | N27: LANÇADO | O27: 46034 | P27: =Tabela1316[[#This Row],[Valor_recibo]] -> 238 | R27: =VLOOKUP(#REF!,[2]Aprovados!A:A,1,0) -> #REF! | U27: PENDENTE | W27: LANÇADO | X27: 132 | Y27: 46030
A28: 22152497 | B28: 46029 | C28: LOURENÇO MALAFAIA | D28: =VLOOKUP(Tabela1316[[#This Row],[Motorista]],Planilha1!A:C,3,0) -> CARRETA | E28: =IF(Tabela1316[[#This Row],[VEICULO]]="CARRETA",5,IF(Tabela1316[[#This Row],[VEICULO]]="TRUCK BAU",3,0)) -> 5 | G28: OSASCO | H28: 146390 / 146389 / 146388 /146387/ 146386 | I28: 46030 | J28: 46030 | K28: 255 | L28: OK | M28: PENDENTE | N28: LANÇADO | O28: 46037 | P28: =Tabela1316[[#This Row],[Valor_recibo]] -> 255 | R28: =VLOOKUP(#REF!,[2]Aprovados!A:A,1,0) -> #REF! | U28: PENDENTE | W28: LANÇADO | X28: 132 | Y28: 46030
A29: 22337774 | B29: 46030 | C29: ROMULO BENEDITO | D29: TRUCK BAU | E29: =IF(Tabela1316[[#This Row],[VEICULO]]="CARRETA",5,IF(Tabela1316[[#This Row],[VEICULO]]="TRUCK BAU",3,0)) -> 3 | G29: TAUBATE | H29: 152366/152368/152369/152370 | I29: 46031 | J29: 46031 | K29: 180 | L29: OK | M29: PENDENTE | N29: LANÇADO | O29: 46042 | P29: =Tabela1316[[#This Row],[Valor_recibo]] -> 180 | R29: =VLOOKUP(#REF!,[2]Aprovados!A:A,1,0) -> #REF! | U29: PENDENTE | W29: LANÇADO | X29: 112.5 | Y29: 46031
A30: 22248659 | B30: 46031 | C30: EVANDRO DE ROSSI | D30: =VLOOKUP(Tabela1316[[#This Row],[Motorista]],Planilha1!A:C,3,0) -> CARRETA | E30: =IF(Tabela1316[[#This Row],[VEICULO]]="CARRETA",5,IF(Tabela1316[[#This Row],[VEICULO]]="TRUCK BAU",3,0)) -> 5 | G30: CAJAMAR | H30: 149815/149814 | I30: 46032 | J30: 46032 | K30: 0 | L30: OK | M30: PENDENTE | O30: 46036 | P30: =Tabela1316[[#This Row],[Valor_recibo]] -> 0 | R30: =VLOOKUP(#REF!,[2]Aprovados!A:A,1,0) -> #REF! | U30: PENDENTE | W30: LANÇADO | X30: 289.5 | Y30: 46031
A31: 22248656 | B31: 46031 | C31: THIAGO BARROS | D31: CARRETA | E31: =IF(Tabela1316[[#This Row],[VEICULO]]="CARRETA",5,IF(Tabela1316[[#This Row],[VEICULO]]="TRUCK BAU",3,0)) -> 5 | G31: CAJAMAR | H31: 149811/149810 | I31: 46032 | J31: 46032 | K31: 0 | L31: OK | M31: PENDENTE | O31: 46036 | P31: =Tabela1316[[#This Row],[Valor_recibo]] -> 0 | R31: =VLOOKUP(#REF!,[2]Aprovados!A:A,1,0) -> #REF! | U31: PENDENTE | W31: LANÇADO | X31: 289.5 | Y31: 46031
A32: 22338012 | B32: 46031 | C32: SEVERINO JOSE DA SILVA | D32: =VLOOKUP(Tabela1316[[#This Row],[Motorista]],Planilha1!A:C,3,0) -> CARRETA | E32: =IF(Tabela1316[[#This Row],[VEICULO]]="CARRETA",5,IF(Tabela1316[[#This Row],[VEICULO]]="TRUCK BAU",3,0)) -> 5 | G32: UBATUBA | H32: 152756/152757152758/152759/152760 | I32: 46032 | J32: 46032 | K32: 560 | L32: OK | M32: PENDENTE | N32: LANÇADO | O32: 46036 | P32: =Tabela1316[[#This Row],[Valor_recibo]] -> 560 | R32: =VLOOKUP(#REF!,[2]Aprovados!A:A,1,0) -> #REF! | U32: PENDENTE | W32: LANÇADO | X32: 327.5 | Y32: 46034
A33: 22338577 | B33: 46031 | C33: WELLINGTON GODOY | D33: TRUCK BAU | E33: =IF(Tabela1316[[#This Row],[VEICULO]]="CARRETA",5,IF(Tabela1316[[#This Row],[VEICULO]]="TRUCK BAU",3,0)) -> 3 | G33: SUMARE | H33: 152711/152712/152713 | I33: 46034 | J33: 46034 | K33: 300 | L33: OK | M33: PENDENTE | N33: LANÇADO | O33: 46036 | P33: =Tabela1316[[#This Row],[Valor_recibo]] -> 300 | R33: =VLOOKUP(#REF!,[2]Aprovados!A:A,1,0) -> #REF! | U33: PENDENTE | W33: LANÇADO | X33: 198.9 | Y33: 46034
A34: 22343340 | B34: 46031 | C34: DANILO JUSTINO MENDES | D34: =VLOOKUP(Tabela1316[[#This Row],[Motorista]],Planilha1!A:C,3,0) -> TRUCK BAU | E34: =IF(Tabela1316[[#This Row],[VEICULO]]="CARRETA",5,IF(Tabela1316[[#This Row],[VEICULO]]="TRUCK BAU",3,0)) -> 3 | G34: AMAPARO | H34: 152690/152691/152692/152693 | I34: 46034 | J34: 46034 | K34: 260 | L34: OK | M34: PENDENTE | N34: LANÇADO | O34: 46036 | P34: =Tabela1316[[#This Row],[Valor_recibo]] -> 260 | R34: =VLOOKUP(#REF!,[2]Aprovados!A:A,1,0) -> #REF! | U34: PENDENTE | W34: LANÇADO | X34: 130.5 | Y34: 46034
A35: 22337798 | B35: 46031 | C35: EMERSON RABELO DIAS | D35: =VLOOKUP(Tabela1316[[#This Row],[Motorista]],Planilha1!A:C,3,0) -> TRUCK BAU | E35: =IF(Tabela1316[[#This Row],[VEICULO]]="CARRETA",5,IF(Tabela1316[[#This Row],[VEICULO]]="TRUCK BAU",3,0)) -> 3 | G35: GUARULHOS | H35: 153202 | I35: 46034 | J35: 46034 | K35: 238 | L35: OK | M35: PENDENTE | N35: LANÇADO | O35: 46036 | P35: =Tabela1316[[#This Row],[Valor_recibo]] -> 238 | R35: =VLOOKUP(#REF!,[2]Aprovados!A:A,1,0) -> #REF! | U35: PENDENTE | W35: LANÇADO | X35: 44.1 | Y35: 46034
A36: 22318653 | B36: 46031 | C36: LOURENÇO MALAFAIA | D36: =VLOOKUP(Tabela1316[[#This Row],[Motorista]],Planilha1!A:C,3,0) -> CARRETA | E36: =IF(Tabela1316[[#This Row],[VEICULO]]="CARRETA",5,IF(Tabela1316[[#This Row],[VEICULO]]="TRUCK BAU",3,0)) -> 5 | G36: CAJAMAR | H36: 153035 | I36: 46035 | J36: 46035 | K36: 532 | L36: OK | M36: PENDENTE | N36: LANÇADO | O36: 46037 | P36: =Tabela1316[[#This Row],[Valor_recibo]] -> 532 | R36: =VLOOKUP(#REF!,[2]Aprovados!A:A,1,0) -> #REF! | U36: PENDENTE | W36: LANÇADO | X36: 289.5 | Y36: 46034
A37: 22341918 | B37: 46031 | C37: JOSE CICERO | D37: =VLOOKUP(Tabela1316[[#This Row],[Motorista]],Planilha1!A:C,3,0) -> CARRETA | E37: =IF(Tabela1316[[#This Row],[VEICULO]]="CARRETA",5,IF(Tabela1316[[#This Row],[VEICULO]]="TRUCK BAU",3,0)) -> 5 | G37: ITAPECERICA DA SERRA | H37: 152824 / 152823 | I37: 46034 | J37: 46034 | K37: 416.5 | L37: OK | M37: PENDENTE | N37: LANÇADO | O37: 46037 | P37: =Tabela1316[[#This Row],[Valor_recibo]] -> 416.5 | R37: =VLOOKUP(#REF!,[2]Aprovados!A:A,1,0) -> #REF! | U37: PENDENTE | W37: LANÇADO | X37: 100 | Y37: 46034
A38: 22348712 | B38: 46031 | C38: LEONARDO BADESKI | D38: =VLOOKUP(Tabela1316[[#This Row],[Motorista]],Planilha1!A:C,3,0) -> CARRETA | E38: =IF(Tabela1316[[#This Row],[VEICULO]]="CARRETA",5,IF(Tabela1316[[#This Row],[VEICULO]]="TRUCK BAU",3,0)) -> 5 | G38: SUMARE | H38: 153023 | I38: 46034 | J38: 46034 | K38: 2000 | L38: OK | M38: PENDENTE | N38: LANÇADO | O38: 46036 | P38: =Tabela1316[[#This Row],[Valor_recibo]] -> 2000 | R38: =VLOOKUP(#REF!,[2]Aprovados!A:A,1,0) -> #REF! | U38: PENDENTE | W38: LANÇADO | X38: 331.5 | Y38: 46034
A39: 22337804 | B39: 46031 | C39: ELTON MORGADO | D39: =VLOOKUP(Tabela1316[[#This Row],[Motorista]],Planilha1!A:C,3,0) -> TRUCK BAU | E39: =IF(Tabela1316[[#This Row],[VEICULO]]="CARRETA",5,IF(Tabela1316[[#This Row],[VEICULO]]="TRUCK BAU",3,0)) -> 3 | G39: CAMPINAS | H39: 152995 | I39: 46034 | J39: 46034 | K39: 238 | L39: OK | M39: PENDENTE | N39: LANÇADO | O39: 46036 | P39: =Tabela1316[[#This Row],[Valor_recibo]] -> 238 | R39: =VLOOKUP(#REF!,[2]Aprovados!A:A,1,0) -> #REF! | U39: PENDENTE | W39: LANÇADO | X39: 216 | Y39: 46034
A40: 22350944 | B40: 46031 | C40: HERMINIO VALENTIM FACHINETTE | D40: TRUCK BAU | E40: =IF(Tabela1316[[#This Row],[VEICULO]]="CARRETA",5,IF(Tabela1316[[#This Row],[VEICULO]]="TRUCK BAU",3,0)) -> 3 | G40: IMPERATRIZ | M40: PENDENTE | N40: PENDENTE | P40: =Tabela1316[[#This Row],[Valor_recibo]] -> 0 | R40: =VLOOKUP(#REF!,[2]Aprovados!A:A,1,0) -> #REF! | U40: PENDENTE | X40: 0
...

Sheet Planilha1
A1: MOTORISTA | B1: CARRETA | C1: PERFIL
A2: SILAS RODRIGO DE SENA | B2: NFK5119 | C2: CARRETA
A3: SEVERINO JOSE DA SILVA | B3: NGX2398 | C3: CARRETA
A4: LEONARDO BADESKI | B4: FCB0J63 | C4: CARRETA
A5: MARIO ADRIANO SILVA | B5: NFS3802 | C5: CARRETA
A6: LOURENÇO MALAFAIA | B6: EFU9730 | C6: CARRETA
A7: DANILO JUSTINO MENDES | C7: TRUCK BAU
A8: IVAN RODRIGUES | B8: NKB5953 | C8: CARRETA
A9: EVANDRO DE ROSSI | B9: NFC4392 | C9: CARRETA
A10: JOSE CICERO | B10: EFV5167 | C10: CARRETA
A11: EMERSON RABELO DIAS | C11: TRUCK BAU
A12: JACKSON MARCELINO | B12: NKB5903 | C12: CARRETA
A13: VALDOMIRO JOSE | C13: TRUCK BAU
A14: CELSO MASSARU SHIMAZAKI | C14: TRUCK BAU
A15: ELTON MORGADO | C15: TRUCK BAU
A16: EMERSON RABELO DIAS | C16: TRUCK BAU
A17: WELLINGTON GODOY | C17: TRUCK
A18: BRUNO FERREIRA OLIVEIRA | B18: NFJ5268 | C18: CARRETA
A19: SEVERINO JOSE DA SILVA | B19: NKB5903 | C19: CARRETA
A20: EVANDRO DE ROSSI | B20: NFC4392 | C20: CARRETA
A21: LEONARDO BADESKI | B21: FCB0J63 | C21: CARRETA
A22: MARIO ADRIANO SILVA | B22: NFS3802 | C22: CARRETA
A23: LOURENÇO MALAFAIA | B23: EFU9730 | C23: CARRETA
A24: LEONARDO BADESKI | B24: FCB0J63 | C24: CARRETA
A25: ALMIR SANTANA DE SOUZA | C25: TRUCK
A26: SEVERINO JOSE DA SILVA | B26: NKB5903 | C26: CARRETA
A27: BRUNO FERREIRA OLIVEIRA | B27: NFJ5268 | C27: CARRETA
A28: MARIO ADRIANO SILVA | B28: NFS3802 | C28: CARRETA
A29: LEONARDO BADESKI | B29: FCB0J63 | C29: CARRETA
A30: LOURENÇO MALAFAIA | B30: EFU9730 | C30: CARRETA
A31: CELSO MASSARU SHIMAZAKI | C31: TRUCK
A32: THIAGO PANZELLI | C32: TRUCK
A33: SILAS RODRIGO DE SENA | B33: NFK5119 | C33: CARRETA
A34: ROMULO BENEDITO | C34: TRUCK
A35: VALDOMIRO JOSE | C35: TRUCK
A36: EVANDRO DE ROSSI | B36: NFC4392 | C36: CARRETA
A37: WELLINGTON GODOY | C37: TRUCK
A38: DANILO JUSTINO MENDES | C38: TRUCK BAU
A39: JOÃO BATISTA - RECUSA MADERITE | C39: TRUCK
A40: JOSE CICERO | B40: EFV5167 | C40: CARRETA
...

Sheet FEVEREIRO 2026
K1: =SUBTOTAL(9,Tabela131617[Valor_recibo]) -> 0 | N1: =SUBTOTAL(9,Tabela131617[Match_Planilha]) -> 0 | O1: =SUBTOTAL(9,O3:O565) -> 0 | R1: =SUBTOTAL(9,R3:R244) -> 0 | S1: PEDAGIO
A2: DT | B2: Data coleta | C2: Motorista | D2: Cliente/Fornecedor | E2: Local | F2: Numero NF | G2: Data canhoto | H2: Data recibo | I2: Valor_recibo | J2: Scaner | K2: APROVAÇÃO_SUZANO | L2: status forms | M2: Data lançamento | N2: Match_Planilha | O2: Dif | P2: DTS APROVADAS | Q2: CTE COMPLEMENTAR | R2: VALOR | S2: STATUS REC CLIENTE | T2: DATA LANÇAMENTO2 | U2: Forms Pedagio | V2: valor | W2: Data lançamento | X2: obs
A3: 22215673 | C3: SEVERINO JOSE DA SILVA | E3: CAJAMAR | K3: PENDENTE | L3: PENDENTE | N3: =Tabela131617[[#This Row],[Valor_recibo]] -> 0 | P3: =VLOOKUP(Tabela131617[[#This Row],[DT]],Aprovados!A:A,1,0) -> #N/A | S3: PENDENTE | U3: LANÇADO | V3: 289.5 | W3: 46021
A4: 22215877 | C4: IZAIAS VARJAO | E4: CAJAMAR | K4: PENDENTE | L4: PENDENTE | N4: =Tabela131617[[#This Row],[Valor_recibo]] -> 0 | P4: =VLOOKUP(Tabela131617[[#This Row],[DT]],Aprovados!A:A,1,0) -> #N/A | S4: PENDENTE | U4: LANÇADO | V4: 289.5 | W4: 46021
A5: 22215879 | C5: LEONARDO BADESKI | E5: CAJAMAR | K5: PENDENTE | L5: PENDENTE | N5: =Tabela131617[[#This Row],[Valor_recibo]] -> 0 | P5: =VLOOKUP(Tabela131617[[#This Row],[DT]],Aprovados!A:A,1,0) -> #N/A | S5: PENDENTE | U5: LANÇADO | V5: 289.5 | W5: 46021
A6: 22219964 | C6: MARIO ADRIANO SILVA | E6: SUMARE | K6: PENDENTE | L6: PENDENTE | N6: =Tabela131617[[#This Row],[Valor_recibo]] -> 0 | P6: =VLOOKUP(Tabela131617[[#This Row],[DT]],Aprovados!A:A,1,0) -> #N/A | S6: PENDENTE | U6: LANÇADO | V6: 331.5 | W6: 46021
A7: 22198401 | C7: JACKSON MARCELINO | E7: CAJAMAR | K7: PENDENTE | L7: PENDENTE | N7: =Tabela131617[[#This Row],[Valor_recibo]] -> 0 | P7: =VLOOKUP(Tabela131617[[#This Row],[DT]],Aprovados!A:A,1,0) -> #N/A | S7: PENDENTE | U7: LANÇADO | V7: 289.5 | W7: 46021
K8: PENDENTE | L8: PENDENTE | N8: =Tabela131617[[#This Row],[Valor_recibo]] -> 0 | P8: =VLOOKUP(Tabela131617[[#This Row],[DT]],Aprovados!A:A,1,0) -> #N/A | S8: PENDENTE | U8: PENDENTE
K9: PENDENTE | L9: PENDENTE | N9: =Tabela131617[[#This Row],[Valor_recibo]] -> 0 | P9: =VLOOKUP(Tabela131617[[#This Row],[DT]],Aprovados!A:A,1,0) -> #N/A | S9: PENDENTE | U9: PENDENTE
K10: PENDENTE | L10: PENDENTE | N10: =Tabela131617[[#This Row],[Valor_recibo]] -> 0 | P10: =VLOOKUP(Tabela131617[[#This Row],[DT]],Aprovados!A:A,1,0) -> #N/A | S10: PENDENTE | U10: PENDENTE
K11: PENDENTE | L11: PENDENTE | N11: =Tabela131617[[#This Row],[Valor_recibo]] -> 0 | P11: =VLOOKUP(Tabela131617[[#This Row],[DT]],Aprovados!A:A,1,0) -> #N/A | S11: PENDENTE | U11: PENDENTE
K12: PENDENTE | L12: PENDENTE | N12: =Tabela131617[[#This Row],[Valor_recibo]] -> 0 | P12: =VLOOKUP(Tabela131617[[#This Row],[DT]],Aprovados!A:A,1,0) -> #N/A | S12: PENDENTE | U12: PENDENTE
K13: PENDENTE | L13: PENDENTE | N13: =Tabela131617[[#This Row],[Valor_recibo]] -> 0 | P13: =VLOOKUP(Tabela131617[[#This Row],[DT]],Aprovados!A:A,1,0) -> #N/A | S13: PENDENTE | U13: PENDENTE
K14: PENDENTE | L14: PENDENTE | N14: =Tabela131617[[#This Row],[Valor_recibo]] -> 0 | P14: =VLOOKUP(Tabela131617[[#This Row],[DT]],Aprovados!A:A,1,0) -> #N/A | S14: PENDENTE | U14: PENDENTE
K15: PENDENTE | L15: PENDENTE | N15: =Tabela131617[[#This Row],[Valor_recibo]] -> 0 | P15: =VLOOKUP(Tabela131617[[#This Row],[DT]],Aprovados!A:A,1,0) -> #N/A | S15: PENDENTE | U15: PENDENTE
K16: PENDENTE | L16: PENDENTE | N16: =Tabela131617[[#This Row],[Valor_recibo]] -> 0 | P16: =VLOOKUP(Tabela131617[[#This Row],[DT]],Aprovados!A:A,1,0) -> #N/A | S16: PENDENTE | U16: PENDENTE
K17: PENDENTE | L17: PENDENTE | N17: =Tabela131617[[#This Row],[Valor_recibo]] -> 0 | P17: =VLOOKUP(Tabela131617[[#This Row],[DT]],Aprovados!A:A,1,0) -> #N/A | S17: PENDENTE | U17: PENDENTE
K18: PENDENTE | L18: PENDENTE | N18: =Tabela131617[[#This Row],[Valor_recibo]] -> 0 | P18: =VLOOKUP(Tabela131617[[#This Row],[DT]],Aprovados!A:A,1,0) -> #N/A | S18: PENDENTE | U18: PENDENTE
K19: PENDENTE | L19: PENDENTE | N19: =Tabela131617[[#This Row],[Valor_recibo]] -> 0 | P19: =VLOOKUP(Tabela131617[[#This Row],[DT]],Aprovados!A:A,1,0) -> #N/A | S19: PENDENTE | U19: PENDENTE
... K244: PENDENTE | L244: PENDENTE | N244: =Tabela131617[[#This Row],[Valor_recibo]] -> 0 | P244: =VLOOKUP(Tabela131617[[#This Row],[DT]],Aprovados!A:A,1,0) -> #N/A | S244: PENDENTE | U244: PENDENTE
K245: PENDENTE | L245: PENDENTE | N245: =Tabela131617[[#This Row],[Valor_recibo]] -> 0 | P245: =VLOOKUP(Tabela131617[[#This Row],[DT]],Aprovados!A:A,1,0) -> #N/A | U245: PENDENTE
K246: PENDENTE | L246: PENDENTE | N246: =Tabela131617[[#This Row],[Valor_recibo]] -> 0 | P246: =VLOOKUP(Tabela131617[[#This Row],[DT]],Aprovados!A:A,1,0) -> #N/A | U246: PENDENTE
K247: PENDENTE | L247: PENDENTE | N247: =Tabela131617[[#This Row],[Valor_recibo]] -> 0 | P247: =VLOOKUP(Tabela131617[[#This Row],[DT]],Aprovados!A:A,1,0) -> #N/A | U247: PENDENTE
K248: PENDENTE | L248: PENDENTE | N248: =Tabela131617[[#This Row],[Valor_recibo]] -> 0 | P248: =VLOOKUP(Tabela131617[[#This Row],[DT]],Aprovados!A:A,1,0) -> #N/A | U248: PENDENTE
K249: PENDENTE | L249: PENDENTE | N249: =Tabela131617[[#This Row],[Valor_recibo]] -> 0 | P249: =VLOOKUP(Tabela131617[[#This Row],[DT]],Aprovados!A:A,1,0) -> #N/A | U249: PENDENTE
K250: PENDENTE | L250: PENDENTE | N250: =Tabela131617[[#This Row],[Valor_recibo]] -> 0 | P250: =VLOOKUP(Tabela131617[[#This Row],[DT]],Aprovados!A:A,1,0) -> #N/A | U250: PENDENTE
K251: PENDENTE | L251: PENDENTE | N251: =Tabela131617[[#This Row],[Valor_recibo]] -> 0 | P251: =VLOOKUP(Tabela131617[[#This Row],[DT]],Aprovados!A:A,1,0) -> #N/A | U251: PENDENTE
K252: PENDENTE | L252: PENDENTE | N252: =Tabela131617[[#This Row],[Valor_recibo]] -> 0 | P252: =VLOOKUP(Tabela131617[[#This Row],[DT]],Aprovados!A:A,1,0) -> #N/A | U252: PENDENTE
K253: PENDENTE | L253: PENDENTE | N253: =Tabela131617[[#This Row],[Valor_recibo]] -> 0 | P253: =VLOOKUP(Tabela131617[[#This Row],[DT]],Aprovados!A:A,1,0) -> #N/A | U253: PENDENTE
K254: PENDENTE | L254: PENDENTE | N254: =Tabela131617[[#This Row],[Valor_recibo]] -> 0 | P254: =VLOOKUP(Tabela131617[[#This Row],[DT]],Aprovados!A:A,1,0) -> #N/A | U254: PENDENTE
K255: PENDENTE | L255: PENDENTE | N255: =Tabela131617[[#This Row],[Valor_recibo]] -> 0 | P255: =VLOOKUP(Tabela131617[[#This Row],[DT]],Aprovados!A:A,1,0) -> #N/A | U255: PENDENTE
K256: PENDENTE | L256: PENDENTE | N256: =Tabela131617[[#This Row],[Valor_recibo]] -> 0 | P256: =VLOOKUP(Tabela131617[[#This Row],[DT]],Aprovados!A:A,1,0) -> #N/A | U256: PENDENTE
... K565: PENDENTE | L565: PENDENTE | N565: =Tabela131617[[#This Row],[Valor_recibo]] -> 0 | P565: =VLOOKUP(Tabela131617[[#This Row],[DT]],Aprovados!A:A,1,0) -> #N/A | U565: PENDENTE
J571: 2W

Sheet MARÇO 2026
K1: =SUBTOTAL(9,Tabela13161718[Valor_recibo]) -> 0 | N1: =SUBTOTAL(9,Tabela13161718[Match_Planilha]) -> 0 | O1: =SUBTOTAL(9,O3:O574) -> 0 | R1: =SUBTOTAL(9,R3:R196) -> 0 | S1: PEDAGIO
A2: DT | B2: Data coleta | C2: Motorista | D2: Cliente/Fornecedor | E2: Local | F2: Numero NF | G2: Data canhoto | H2: Data recibo | I2: Valor_recibo | J2: Scaner | K2: APROVAÇÃO_SUZANO | L2: status forms | M2: Data lançamento | N2: Match_Planilha | O2: Dif | P2: DTS APROVADAS | Q2: CTE COMPLEMENTAR | R2: VALOR | S2: STATUS REC CLIENTE | T2: DATA LANÇAMENTO2 | U2: Forms Pedagio | V2: Valor | W2: Data lançamento | X2: obs
K3: PENDENTE | L3: PENDENTE | N3: =Tabela13161718[[#This Row],[Valor_recibo]] -> 0 | P3: =VLOOKUP(Tabela13161718[[#This Row],[DT]],Aprovados!A:A,1,0) -> #N/A | S3: PENDENTE | U3: PENDENTE
K4: PENDENTE | L4: PENDENTE | N4: =Tabela13161718[[#This Row],[Valor_recibo]] -> 0 | P4: =VLOOKUP(Tabela13161718[[#This Row],[DT]],Aprovados!A:A,1,0) -> #N/A | S4: PENDENTE | U4: PENDENTE
K5: PENDENTE | L5: PENDENTE | N5: =Tabela13161718[[#This Row],[Valor_recibo]] -> 0 | P5: =VLOOKUP(Tabela13161718[[#This Row],[DT]],Aprovados!A:A,1,0) -> #N/A | S5: PENDENTE | U5: PENDENTE
K6: PENDENTE | L6: PENDENTE | N6: =Tabela13161718[[#This Row],[Valor_recibo]] -> 0 | P6: =VLOOKUP(Tabela13161718[[#This Row],[DT]],Aprovados!A:A,1,0) -> #N/A | S6: PENDENTE | U6: PENDENTE
K7: PENDENTE | L7: PENDENTE | N7: =Tabela13161718[[#This Row],[Valor_recibo]] -> 0 | P7: =VLOOKUP(Tabela13161718[[#This Row],[DT]],Aprovados!A:A,1,0) -> #N/A | S7: PENDENTE | U7: PENDENTE
K8: PENDENTE | L8: PENDENTE | N8: =Tabela13161718[[#This Row],[Valor_recibo]] -> 0 | P8: =VLOOKUP(Tabela13161718[[#This Row],[DT]],Aprovados!A:A,1,0) -> #N/A | S8: PENDENTE | U8: PENDENTE
K9: PENDENTE | L9: PENDENTE | N9: =Tabela13161718[[#This Row],[Valor_recibo]] -> 0 | P9: =VLOOKUP(Tabela13161718[[#This Row],[DT]],Aprovados!A:A,1,0) -> #N/A | S9: PENDENTE | U9: PENDENTE
K10: PENDENTE | L10: PENDENTE | N10: =Tabela13161718[[#This Row],[Valor_recibo]] -> 0 | P10: =VLOOKUP(Tabela13161718[[#This Row],[DT]],Aprovados!A:A,1,0) -> #N/A | S10: PENDENTE | U10: PENDENTE
K11: PENDENTE | L11: PENDENTE | N11: =Tabela13161718[[#This Row],[Valor_recibo]] -> 0 | P11: =VLOOKUP(Tabela13161718[[#This Row],[DT]],Aprovados!A:A,1,0) -> #N/A | S11: PENDENTE | U11: PENDENTE
K12: PENDENTE | L12: PENDENTE | N12: =Tabela13161718[[#This Row],[Valor_recibo]] -> 0 | P12: =VLOOKUP(Tabela13161718[[#This Row],[DT]],Aprovados!A:A,1,0) -> #N/A | S12: PENDENTE | U12: PENDENTE
K13: PENDENTE | L13: PENDENTE | N13: =Tabela13161718[[#This Row],[Valor_recibo]] -> 0 | P13: =VLOOKUP(Tabela13161718[[#This Row],[DT]],Aprovados!A:A,1,0) -> #N/A | S13: PENDENTE | U13: PENDENTE
K14: PENDENTE | L14: PENDENTE | N14: =Tabela13161718[[#This Row],[Valor_recibo]] -> 0 | P14: =VLOOKUP(Tabela13161718[[#This Row],[DT]],Aprovados!A:A,1,0) -> #N/A | S14: PENDENTE | U14: PENDENTE
... K42: PENDENTE | L42: PENDENTE | N42: =Tabela13161718[[#This Row],[Valor_recibo]] -> 0 | P42: =VLOOKUP(Tabela13161718[[#This Row],[DT]],Aprovados!A:A,1,0) -> #N/A | S42: PENDENTE | U42: PENDENTE
K43: PENDENTE | L43: PENDENTE | N43: =Tabela13161718[[#This Row],[Valor_recibo]] -> 0 | P43: =VLOOKUP(Tabela13161718[[#This Row],[DT]],Aprovados!A:A,1,0) -> #N/A | S43: PENDENTE | U43: PENDENTE | X43: Valor pedagio divergente no espelho dt
K44: PENDENTE | L44: PENDENTE | N44: =Tabela13161718[[#This Row],[Valor_recibo]] -> 0 | P44: =VLOOKUP(Tabela13161718[[#This Row],[DT]],Aprovados!A:A,1,0) -> #N/A | S44: PENDENTE | U44: PENDENTE
K45: PENDENTE | L45: PENDENTE | N45: =Tabela13161718[[#This Row],[Valor_recibo]] -> 0 | P45: =VLOOKUP(Tabela13161718[[#This Row],[DT]],Aprovados!A:A,1,0) -> #N/A | S45: PENDENTE | U45: PENDENTE
K46: PENDENTE | L46: PENDENTE | N46: =Tabela13161718[[#This Row],[Valor_recibo]] -> 0 | P46: =VLOOKUP(Tabela13161718[[#This Row],[DT]],Aprovados!A:A,1,0) -> #N/A | S46: PENDENTE | U46: PENDENTE
K47: PENDENTE | L47: PENDENTE | N47: =Tabela13161718[[#This Row],[Valor_recibo]] -> 0 | P47: =VLOOKUP(Tabela13161718[[#This Row],[DT]],Aprovados!A:A,1,0) -> #N/A | S47: PENDENTE | U47: PENDENTE
K48: PENDENTE | L48: PENDENTE | N48: =Tabela13161718[[#This Row],[Valor_recibo]] -> 0 | P48: =VLOOKUP(Tabela13161718[[#This Row],[DT]],Aprovados!A:A,1,0) -> #N/A | S48: PENDENTE | U48: PENDENTE
K49: PENDENTE | L49: PENDENTE | N49: =Tabela13161718[[#This Row],[Valor_recibo]] -> 0 | P49: =VLOOKUP(Tabela13161718[[#This Row],[DT]],Aprovados!A:A,1,0) -> #N/A | S49: PENDENTE | U49: PENDENTE
K50: PENDENTE | L50: PENDENTE | N50: =Tabela13161718[[#This Row],[Valor_recibo]] -> 0 | P50: =VLOOKUP(Tabela13161718[[#This Row],[DT]],Aprovados!A:A,1,0) -> #N/A | S50: PENDENTE | U50: PENDENTE
K51: PENDENTE | L51: PENDENTE | N51: =Tabela13161718[[#This Row],[Valor_recibo]] -> 0 | P51: =VLOOKUP(Tabela13161718[[#This Row],[DT]],Aprovados!A:A,1,0) -> #N/A | S51: PENDENTE | U51: PENDENTE
K52: PENDENTE | L52: PENDENTE | N52: =Tabela13161718[[#This Row],[Valor_recibo]] -> 0 | P52: =VLOOKUP(Tabela13161718[[#This Row],[DT]],Aprovados!A:A,1,0) -> #N/A | S52: PENDENTE | U52: PENDENTE
K53: PENDENTE | L53: PENDENTE | N53: =Tabela13161718[[#This Row],[Valor_recibo]] -> 0 | P53: =VLOOKUP(Tabela13161718[[#This Row],[DT]],Aprovados!A:A,1,0) -> #N/A | S53: PENDENTE | U53: PENDENTE
K54: PENDENTE | L54: PENDENTE | N54: =Tabela13161718[[#This Row],[Valor_recibo]] -> 0 | P54: =VLOOKUP(Tabela13161718[[#This Row],[DT]],Aprovados!A:A,1,0) -> #N/A | S54: PENDENTE | U54: PENDENTE
K55: PENDENTE | L55: PENDENTE | N55: =Tabela13161718[[#This Row],[Valor_recibo]] -> 0 | P55: =VLOOKUP(Tabela13161718[[#This Row],[DT]],Aprovados!A:A,1,0) -> #N/A | S55: PENDENTE | U55: PENDENTE
... K219: PENDENTE | L219: PENDENTE | N219: =Tabela13161718[[#This Row],[Valor_recibo]] -> 0 | P219: =VLOOKUP(Tabela13161718[[#This Row],[DT]],Aprovados!A:A,1,0) -> #N/A | S219: PENDENTE | U219: PENDENTE
K220: PENDENTE | L220: PENDENTE | N220: =Tabela13161718[[#This Row],[Valor_recibo]] -> 0 | P220: RECUSADO | S220: PENDENTE | U220: PENDENTE
K221: PENDENTE | L221: PENDENTE | N221: =Tabela13161718[[#This Row],[Valor_recibo]] -> 0 | P221: =VLOOKUP(Tabela13161718[[#This Row],[DT]],Aprovados!A:A,1,0) -> #N/A | S221: PENDENTE | U221: PENDENTE
K222: APROVADO | L222: PENDENTE | N222: =Tabela13161718[[#This Row],[Valor_recibo]] -> 0 | P222: =VLOOKUP(Tabela13161718[[#This Row],[DT]],Aprovados!A:A,1,0) -> #N/A | S222: PENDENTE | U222: PENDENTE
K223: PENDENTE | L223: PENDENTE | N223: =Tabela13161718[[#This Row],[Valor_recibo]] -> 0 | P223: =VLOOKUP(Tabela13161718[[#This Row],[DT]],Aprovados!A:A,1,0) -> #N/A | S223: PENDENTE | U223: PENDENTE
K224: PENDENTE | L224: PENDENTE | N224: =Tabela13161718[[#This Row],[Valor_recibo]] -> 0 | P224: =VLOOKUP(Tabela13161718[[#This Row],[DT]],Aprovados!A:A,1,0) -> #N/A | S224: PENDENTE | U224: PENDENTE
K225: APROVADO | L225: PENDENTE | N225: =Tabela13161718[[#This Row],[Valor_recibo]] -> 0 | P225: =VLOOKUP(Tabela13161718[[#This Row],[DT]],Aprovados!A:A,1,0) -> #N/A | S225: PENDENTE | U225: PENDENTE
K226: PENDENTE | L226: PENDENTE | N226: =Tabela13161718[[#This Row],[Valor_recibo]] -> 0 | P226: =VLOOKUP(Tabela13161718[[#This Row],[DT]],Aprovados!A:A,1,0) -> #N/A | S226: PENDENTE | U226: PENDENTE
K227: PENDENTE | L227: PENDENTE | N227: =Tabela13161718[[#This Row],[Valor_recibo]] -> 0 | P227: =VLOOKUP(Tabela13161718[[#This Row],[DT]],Aprovados!A:A,1,0) -> #N/A | S227: PENDENTE | U227: PENDENTE
K228: PENDENTE | L228: PENDENTE | N228: =Tabela13161718[[#This Row],[Valor_recibo]] -> 0 | P228: =VLOOKUP(Tabela13161718[[#This Row],[DT]],Aprovados!A:A,1,0) -> #N/A | S228: PENDENTE | U228: PENDENTE
K229: PENDENTE | L229: PENDENTE | N229: =Tabela13161718[[#This Row],[Valor_recibo]] -> 0 | P229: =VLOOKUP(Tabela13161718[[#This Row],[DT]],Aprovados!A:A,1,0) -> #N/A | S229: PENDENTE | U229: PENDENTE
L230: PENDENTE | N230: =Tabela13161718[[#This Row],[Valor_recibo]] -> 0 | P230: =VLOOKUP(Tabela13161718[[#This Row],[DT]],Aprovados!A:A,1,0) -> #N/A | S230: PENDENTE | U230: PENDENTE
...

Sheet ABRIL 2026
K1: =SUBTOTAL(9,Tabela1316171819[Valor_recibo]) -> 0 | N1: =SUBTOTAL(9,Tabela1316171819[Match_Planilha]) -> 0 | O1: =SUBTOTAL(9,O3:O570) -> 0 | R1: =SUBTOTAL(9,R3:R189) -> 0 | S1: PEDAGIO | V1: =SUM(Tabela1316171819[[Valor ]]) -> 0
A2: DT | B2: Data coleta | C2: Cliente/Fornecedor | D2: Motorista | E2: Local | F2: Numero NF | G2: Data canhoto | H2: Data recibo | I2: Valor_recibo | J2: Scaner | K2: APROVAÇÃO_SUZANO | L2: status forms | M2: Data lançamento | N2: Match_Planilha | O2: Dif | P2: DTS APROVADAS | Q2: CTE COMPLEMENTAR | R2: VALOR | S2: STATUS REC CLIENTE | T2: DATA LANÇAMENTO2 | U2: Forms Pedagio | V2: Valor | W2: Data lançamento | X2: obs
K3: PENDENTE | L3: PENDENTE | N3: =Tabela1316171819[[#This Row],[Valor_recibo]] -> 0 | P3: =VLOOKUP(Tabela1316171819[[#This Row],[DT]],Aprovados!A:A,1,0) -> #N/A | U3: PENDENTE
K4: PENDENTE | L4: PENDENTE | N4: =Tabela1316171819[[#This Row],[Valor_recibo]] -> 0 | P4: =VLOOKUP(Tabela1316171819[[#This Row],[DT]],Aprovados!A:A,1,0) -> #N/A | U4: PENDENTE
K5: PENDENTE | L5: PENDENTE | N5: =Tabela1316171819[[#This Row],[Valor_recibo]] -> 0 | P5: =VLOOKUP(Tabela1316171819[[#This Row],[DT]],Aprovados!A:A,1,0) -> #N/A | U5: PENDENTE
K6: PENDENTE | L6: PENDENTE | N6: =Tabela1316171819[[#This Row],[Valor_recibo]] -> 0 | P6: =VLOOKUP(Tabela1316171819[[#This Row],[DT]],Aprovados!A:A,1,0) -> #N/A | U6: PENDENTE
K7: PENDENTE | L7: PENDENTE | N7: =Tabela1316171819[[#This Row],[Valor_recibo]] -> 0 | P7: =VLOOKUP(Tabela1316171819[[#This Row],[DT]],Aprovados!A:A,1,0) -> #N/A | U7: PENDENTE
K8: PENDENTE | L8: PENDENTE | N8: =Tabela1316171819[[#This Row],[Valor_recibo]] -> 0 | P8: =VLOOKUP(Tabela1316171819[[#This Row],[DT]],Aprovados!A:A,1,0) -> #N/A | U8: PENDENTE
K9: PENDENTE | L9: PENDENTE | N9: =Tabela1316171819[[#This Row],[Valor_recibo]] -> 0 | P9: =VLOOKUP(Tabela1316171819[[#This Row],[DT]],Aprovados!A:A,1,0) -> #N/A | U9: PENDENTE
K10: PENDENTE | L10: PENDENTE | N10: =Tabela1316171819[[#This Row],[Valor_recibo]] -> 0 | P10: =VLOOKUP(Tabela1316171819[[#This Row],[DT]],Aprovados!A:A,1,0) -> #N/A | U10: PENDENTE
K11: PENDENTE | L11: PENDENTE | N11: =Tabela1316171819[[#This Row],[Valor_recibo]] -> 0 | P11: =VLOOKUP(Tabela1316171819[[#This Row],[DT]],Aprovados!A:A,1,0) -> #N/A | U11: PENDENTE
